Workbook

Sheet totaal
D1: Trainings resultaat
B5: June 17, 2025
A6: Hf | B6: ='June 17, 2025'!D60
A7: Bf | B7: ='June 17, 2025'!D62
A8: Con | B8: ='June 17, 2025'!D66
A9: Herst | B9: ='June 17, 2025'!D68
A10: gewicht | B10: ='June 17, 2025'!B33
A11: bovendruk | B11: ='June 17, 2025'!B39
A12: onderdruk | B12: ='June 17, 2025'!B40

Sheet June 17, 2025
D6: Healthcheck Resultaten
A8: datum: | B8: June 17, 2025
A9: naam:
A10: leeftijd:
A11: tel.nr::
A12: email:
A14: De resultaten worden in kleur en getal weergegeven
A15: Betekenis van de kleuren
B16: goed, binnen de norm
B17: aandachtspunt
B18: actie ondernemen
A21: Verkorte gezondheids vragenlijst
A22: Gezondheid | D22: opmerkingen
A23: Klachten | C23: nee
A24: Medicijnen | C24: nee
A25: Onder behandeling | C25: nee
A26: Sport | C26: ja
A27: Roken | C27: nee
B31: uw score | C31: norm
A32: lengte | B32: 1.79
A33: gewicht | B33: 79 | C33: =(B32-1)*100 | D33: hier boven is overgewicht
A34: BMI | B34: =B33/(B32*B32) | C34: onder 25 | D34: gewicht in verhouding tot de lengte
A35: vet % man | B35: 20 | C35: onder 20 | D35: percentage vet t.o.v. het totale gewicht
A36: vet % vrouw | B36: 32 | C36: onder 30 | D36: percentage vet t.o.v. het totale gewicht
A38: bloeddruk | B38: uw score | C38: norm
A39: boven | B39: 120 | C39: 120 | D39: de maximale druk bij samentrekking van het hart
A40: onder | B40: 80 | C40: 80 | D40: de minimale druk bij ontspanning van het hart
A43: Uw verbranding in rust
C44: uw score | D44: norm
A45: uw verbranding | C45: =0.7+((D62-10)*0.015) | D45: 0.7
C47: score | D47: capaciteit | F47: Geef een cijfer voor uw conditie in het het grijze vakje
A48: uw conditie | C48: 7 | D48: 240 | E48: watts(= max kracht in training) | H48: man | I48: vrouw
H49: 2 | I49: 1 | J49: geen beweging
A50: Berekening van extra calorie verbruik door sport | H50: 3 | I50: 2 | J50: weinig
A51: trainingskracht | C51: =D48*0.5 | D51: per week | E51: per/dag | H51: 4 | I51: 3 | J51: redelijk
A52: aantal min/week | C52: 180 | D52: =C51*0.08*C52 | E52: =D52/7 | F52: calorieen | H52: 5 | I52: 4 | J52: aardig
H53: 6 | I53: 5 | J53: goed
A54: Berekening van uw calorie inname per dag | H54: 7 | I54: 6 | J54: sportief
A55: goede verbranding | C55: aan de hoge kant | E55: te hoog | H55: 8 | I55: 7 | J55: zeer sportief
A56: =B33*24 | B56: =A56*1.01 | C56: =A56*1.02 | D56: =A56*1.03 | E56: =A56*1.04 | F56: zonder sporten | H56: 9 | I56: 8 | J56: topsporter
...
